Workbook
Name Tabla11: Tabla_Pivot_Facturacion[]

Sheet Panel Entrada
B1: TAPERIA DE CALDES · PANEL DE ENTRADA RÁPIDA
B2: Pega los datos del TPV en las zonas indicadas. Todo se actualiza automáticamente.
B4: RESUMEN DE DATOS CARGADOS
B5: Fuente de datos | C5: Registros | D5: Rango fechas | E5: Dónde pegar | F5: Estado
B6: ⚽ Tickets Caja 1 (Tabla 8) | C6: =COUNTA('Detalle Turnos'!I3:I5022)-1 -> 1793 | D6: =TEXT(MIN('Detalle Turnos'!I3:I5022),"dd/mm/yy")&" → "&TEXT(MAX('Detalle Turnos'!I3:I5022),"dd/mm/yy") -> 02/01/yy → 01/05/yy | E6: Detalle Turnos' I:O | F6: =IF(C6>0,"✅ "&C6&" tickets","❌ Vacío") -> ✅ 1793 tickets
B7: 🎽 Tickets Caja 2 (Tabla 9) | C7: =COUNTA('Detalle Turnos'!Q3:Q4992)-1 -> 204 | D7: =TEXT(MIN('Detalle Turnos'!Q3:Q4992),"dd/mm/yy")&" → "&TEXT(MAX('Detalle Turnos'!Q3:Q4992),"dd/mm/yy") -> 02/01/yy → 30/04/yy | E7: Detalle Turnos' Q:V | F7: =IF(C7>0,"✅ "&C7&" tickets","❌ Vacío") -> ✅ 204 tickets
B8: 👥 Horarios Personal | C8: =COUNTA('Horarios Personal'!A5:A602)-COUNTBLANK('Horarios Personal'!A5:A602) -> 598 | D8: =IFERROR(TEXT(MIN(DATEVALUE(LEFT('Horarios Personal'!A5,2)&"/"&MID('Horarios Personal'!A5,4,2)&"/"&RIGHT('Horarios Personal'!A5,4))),"dd/mm/yy")&" → "&'Horarios Personal'!A551,"Ene → Abr 2026") -> Ene → Abr 2026 | E8: Horarios Personal' A5+ | F8: =IF(C8>0,"✅ "&C8&" registros","❌ Vacío") -> ✅ 598 registros
B9: 📊 Ventas por Producto (Caja 1) | C9: =COUNTA('Ventas Caja 1'!B5:B7550) -> 5693 | D9: =IFERROR(TEXT(MIN('Ventas Caja 1'!B5:B7550),"dd/mm/yy")&" → "&TEXT(MAX('Ventas Caja 1'!B5:B7550),"dd/mm/yy"),"") -> 02/01/yy → 01/05/yy | E9: Ventas Caja 1' B5+ | F9: =IF(C9>0,"✅ "&C9&" líneas","❌ Vacío") -> ✅ 5693 líneas
B11: INSTRUCCIONES DE PEGADO
B13: ❶ TICKETS CAJA 1 — Tabla 8
B14: 📁 Hoja destino: | C14: Detalle Turnos
B15: 📍 Celda inicio: | C15: I (debajo del último dato)
B16: 📋 Columnas: | C16: I=Fecha | J=Hora | K=Importe | L=Pax | M=Día | N=Turno
B17: ➡️ Alimenta: | C17: Caja 1 → Facturación 2026 → Dashboard
B19: ❷ TICKETS CAJA 2 — Tabla 9
B20: 📁 Hoja destino: | C20: Detalle Turnos
B21: 📍 Celda inicio: | C21: Q (debajo del último dato)
B22: 📋 Columnas: | C22: Q=Fecha | R=Hora | S=Turno | T=Pax | U=Importe
B23: ➡️ Alimenta: | C23: Caja 2 → Facturación 2026 → Dashboard
B25: ❸ HORARIOS PERSONAL
B26: 📁 Hoja destino: | C26: Horarios Personal
B27: 📍 Celda inicio: | C27: A (debajo fila 551 o último dato)
B28: 📋 Columnas: | C28: A=Fecha(dd/mm/yyyy) | B=Día | C=Turno | D=Nombre | E=Entrada | F=Salida
B29: ➡️ Alimenta: | C29: Resumen Empleado → Facturación (Coste) → Cajas → Dashboard
B30: ⚠️ Importante: | C30: Fechas como TEXTO dd/mm/yyyy. Horas como decimales (0.29=7:00, 0.79=19:00)
B32: ❹ VENTAS POR PRODUCTO
B33: 📁 Hoja destino: | C33: Ventas Caja 1 (o nueva hoja)
B34: 📍 Celda inicio: | C34: B (debajo del último dato, actual: B22152)
B35: 📋 Columnas: | C35: B=Fecha | C=Familia | D=Producto | E=Cantidad | F=PVP | G=Total | H=Neto | I=%Cons | J=Coste | K=T.Coste
B36: ➡️ Alimenta: | C36: Análisis de productos y márgenes (pendiente de conectar)
B38: CADENA DE ACTUALIZACIÓN AUTOMÁTICA
B39: Pegas tickets → Detalle Turnos agrega → Cajas calculan → Facturación consolida → Dashboard muestra KPIs
B41: 📦 Tickets TPV | C41: ➡️ | D41: Detalle Turnos | E41: ➡️ | F41: Caja 1 + Caja 2
D42: (agrega por fecha+turno) | F42: (comensales, subtotal, ticket medio)
B44: 👥 Horarios | C44: ➡️ | D44: Facturación 2026 (J) | E44: ➡️ | F44: Dashboard Gerencia
D45: (coste personal por día) | F45: (KPIs, ratio, alertas)

Sheet Dashboard Gerencia
A1: TAPERIA DE CALDES · DASHBOARD GERENCIA — VISIÓN 360°
A2: Actualizado: Abril 2026 · Datos: Enero–Abril 2026 · Modelo basado en 250+ días históricos (2025) + datos reales 2026
A4: KPIs OPERATIVOS — ENERO A ABRIL 2026
A5: FACTURACIÓN REAL ENE–ABR | C5: FACTURACIÓN PREVISTA | E5: COSTE PERSONAL (CORREGIDO) | G5: RATIO COSTE/VENTA | I5: MARGEN BRUTO ENE–ABR | K5: MEJOR DÍA | M5: AHORRO FICHAJES CORR.
A6: =TEXT('Facturación 2026'!P16,"#.##0"&" €") -> 105.333 € | C6: =TEXT('Facturación 2026'!Q16,"#.##0"&" €") -> 390.218 € | E6: {=TEXT(SUMPRODUCT(('Facturación 2026'!$J$4:$J$253)*1),"#.##0"&" €")} -> 25.355 € | G6: {=TEXT(IFERROR(SUMPRODUCT(('Facturación 2026'!$J$4:$J$253)*1)/'Facturación 2026'!P16,0),"0,0%")} -> 24,1% | I6: {=TEXT('Facturación 2026'!P16-SUMPRODUCT(('Facturación 2026'!$J$4:$J$253)*1),"#.##0"&" €")} -> 79.978 € | K6: =TEXT(INDEX('Facturación 2026'!$A$4:$A$253,MATCH(MAX('Facturación 2026'!$F$4:$F$253),'Facturación 2026'!$F$4:$F$253,0)),"dd/mm")&" — "&TEXT(MAX('Facturación 2026'!$F$4:$F$253),"#.##0")&"€" -> 07/02 — 3.908€ | M6: −1.366 €
A9: FACTURACIÓN MENSUAL 2026 vs 2025 + PROYECCIÓN
A10: Mes | B10: Real 2025 | C10: Prev. 2026 | D10: Real 2026 | E10: Coste Pers. | F10: Margen € | G10: % Coste | H10: vs 2025 | I10: vs Prev. | J10: Índice | K10: Días | L10: Comentario
A11: Enero | B11: 24020 | C11: 35000 | D11: ='Facturación 2026'!P4 -> 26444.12 | E11: {=SUMPRODUCT((MONTH('Facturación 2026'!$A$4:$A$253)=1)*('Facturación 2026'!$J$4:$J$253)*1)} -> 10707.093 | F11: =IFERROR(D11-E11,"") -> 15737.027 | G11: =IFERROR(E11/D11,"") -> 0.40489502 | H11: =IFERROR((D11-B11)/B11,"") -> 0.1009209 | I11: =IFERROR((D11-C11)/C11,"") -> -0.24445371 | J11: 0.72 | K11: {=SUMPRODUCT((MONTH('Facturación 2026'!$A$4:$A$253)=1)*('Facturación 2026'!$F$4:$F$253>0)*1)} -> 22 | L11: Real ✓
A12: Febrero | B12: 26309 | C12: 32000 | D12: ='Facturación 2026'!P5 -> 26991.51 | E12: {=SUMPRODUCT((MONTH('Facturación 2026'!$A$4:$A$253)=2)*('Facturación 2026'!$J$4:$J$253)*1)} -> 8426.145 | F12: =IFERROR(D12-E12,"") -> 18565.365 | G12: =IFERROR(E12/D12,"") -> 0.31217761 | H12: =IFERROR((D12-B12)/B12,"") -> 0.025942073 | I12: =IFERROR((D12-C12)/C12,"") -> -0.15651531 | J12: 0.88 | K12: {=SUMPRODUCT((MONTH('Facturación 2026'!$A$4:$A$253)=2)*('Facturación 2026'!$F$4:$F$253>0)*1)} -> 16 | L12: Real ✓
A13: Marzo | B13: 20665 | C13: 28000 | D13: ='Facturación 2026'!P6 -> 20240.31 | E13: {=SUMPRODUCT((MONTH('Facturación 2026'!$A$4:$A$253)=3)*('Facturación 2026'!$J$4:$J$253)*1)} -> 6221.6925 | F13: =IFERROR(D13-E13,"") -> 14018.618 | G13: =IFERROR(E13/D13,"") -> 0.30739117 | H13: =IFERROR((D13-B13)/B13,"") -> -0.020551173 | I13: =IFERROR((D13-C13)/C13,"") -> -0.27713179 | J13: 0.95 | K13: {=SUMPRODUCT((MONTH('Facturación 2026'!$A$4:$A$253)=3)*('Facturación 2026'!$F$4:$F$253>0)*1)} -> 15 | L13: Real ✓
A14: Abril | B14: 28883 | C14: 26000 | D14: ='Facturación 2026'!P7 -> 31581.437 | E14: {=SUMPRODUCT((MONTH('Facturación 2026'!$A$4:$A$253)=4)*('Facturación 2026'!$J$4:$J$253)*1)} -> 0 | F14: =IFERROR(D14-E14,"") -> 31581.437 | G14: =IFERROR(E14/D14,"") -> 0 | H14: =IFERROR((D14-B14)/B14,"") -> 0.093426479 | I14: =IFERROR((D14-C14)/C14,"") -> 0.21467065 | J14: 0.98 | K14: {=SUMPRODUCT((MONTH('Facturación 2026'!$A$4:$A$253)=4)*('Facturación 2026'!$F$4:$F$253>0)*1)} -> 22 | L14: Parcial
A15: Mayo | B15: 24855 | C15: 25000 | F15: =IFERROR(D15-E15,"") -> 0 | G15: =IFERROR(E15/D15,"") | H15: =IFERROR((D15-B15)/B15,"") -> -1 | I15: =IFERROR((D15-C15)/C15,"") -> -1 | J15: 0.92 | K15: 20 | L15: Previsto
A16: Junio | B16: 34531 | C16: 30000 | F16: =IFERROR(D16-E16,"") -> 0 | G16: =IFERROR(E16/D16,"") | H16: =IFERROR((D16-B16)/B16,"") -> -1 | I16: =IFERROR((D16-C16)/C16,"") -> -1 | J16: 1.1 | K16: 22 | L16: Previsto
A17: Julio | B17: 44025 | C17: 50000 | F17: =IFERROR(D17-E17,"") -> 0 | G17: =IFERROR(E17/D17,"") | H17: =IFERROR((D17-B17)/B17,"") -> -1 | I17: =IFERROR((D17-C17)/C17,"") -> -1 | J17: 1.38 | K17: 23 | L17: Previsto — Escaldàrium
A18: Agosto | B18: 60081 | C18: 65000 | F18: =IFERROR(D18-E18,"") -> 0 | G18: =IFERROR(E18/D18,"") | H18: =IFERROR((D18-B18)/B18,"") -> -1 | I18: =IFERROR((D18-C18)/C18,"") -> -1 | J18: 1.48 | K18: 27 | L18: Previsto — pico
A19: Septiembre | B19: 30862 | C19: 38000 | F19: =IFERROR(D19-E19,"") -> 0 | G19: =IFERROR(E19/D19,"") | H19: =IFERROR((D19-B19)/B19,"") -> -1 | I19: =IFERROR((D19-C19)/C19,"") -> -1 | J19: 1.18 | K19: 21 | L19: Previsto
A20: Octubre | B20: 38013 | C20: 42000 | F20: =IFERROR(D20-E20,"") -> 0 | G20: =IFERROR(E20/D20,"") | H20: =IFERROR((D20-B20)/B20,"") -> -1 | I20: =IFERROR((D20-C20)/C20,"") -> -1 | J20: 1.22 | K20: 22 | L20: Previsto — Festa Major
A21: Noviembre | B21: 19490 | C21: 28000 | F21: =IFERROR(D21-E21,"") -> 0 | G21: =IFERROR(E21/D21,"") | H21: =IFERROR((D21-B21)/B21,"") -> -1 | I21: =IFERROR((D21-C21)/C21,"") -> -1 | J21: 1.02 | K21: 12 | L21: Previsto
A22: Diciembre | B22: 19797 | C22: 35000 | F22: =IFERROR(D22-E22,"") -> 0 | G22: =IFERROR(E22/D22,"") | H22: =IFERROR((D22-B22)/B22,"") -> -1 | I22: =IFERROR((D22-C22)/C22,"") -> -1 | J22: 1.18 | K22: 14 | L22: Previsto — Fira Nadal
A23: TOTAL ANUAL | B23: =SUM(B11:B22) -> 371531 | C23: =SUM(C11:C22) -> 434000 | D23: =SUM(D11:D22) -> 105257.38 | E23: =SUM(E11:E22) -> 25354.93 | F23: =IFERROR(D23-E23,"") -> 79902.447 | G23: =IFERROR(E23/D23,"") -> 0.24088506
A25: EFICIENCIA OPERATIVA — RATIO COSTE PERSONAL / VENTAS
A26: Día semana | B26: Fact. media | C26: Coste medio | D26: Ratio % | E26: Semáforo | F26: Objetivo % | G26: Estado | H26: Personal ideal | I26: Recomendación
A27: Miércoles | B27: {=IFERROR(SUMPRODUCT((WEEKDAY('Facturación 2026'!$A$4:$A$253,2)=3)*'Facturación 2026'!$F$4:$F$253)/SUMPRODUCT((WEEKDAY('Facturación 2026'!$A$4:$A$253,2)=3)*('Facturación 2026'!$F$4:$F$253>0)*1),0)} -> 780.6944 | C27: {=IFERROR(SUMPRODUCT((WEEKDAY('Facturación 2026'!$A$4:$A$253,2)=3)*'Facturación 2026'!$J$4:$J$253)/SUMPRODUCT((WEEKDAY('Facturación 2026'!$A$4:$A$253,2)=3)*('Facturación 2026'!$F$4:$F$253>0)*1),0)} -> 288.9715 | D27: =IFERROR(C27/B27,"—") -> 0.37014676 | E27: =IF(D27="—","",IF(D27<=0.33,"🟢",IF(D27<=0.38,"🟡","🔴"))) -> 🟡 | F27: 0.38 | G27: =IF(B27=0,"—",IF(D27<=F27,"🟢 OK","🔴 Excede")) -> 🟢 OK | H27: 3 pers. | I27: Nuevo horario sin MA mejora ratio
A28: Jueves | B28: {=IFERROR(SUMPRODUCT((WEEKDAY('Facturación 2026'!$A$4:$A$253,2)=4)*'Facturación 2026'!$F$4:$F$253)/SUMPRODUCT((WEEKDAY('Facturación 2026'!$A$4:$A$253,2)=4)*('Facturación 2026'!$F$4:$F$253>0)*1),0)} -> 1055.4893 | C28: {=IFERROR(SUMPRODUCT((WEEKDAY('Facturación 2026'!$A$4:$A$253,2)=4)*'Facturación 2026'!$J$4:$J$253)/SUMPRODUCT((WEEKDAY('Facturación 2026'!$A$4:$A$253,2)=4)*('Facturación 2026'!$F$4:$F$253>0)*1),0)} -> 293.04067 | D28: =IFERROR(C28/B28,"—") -> 0.27763491 | E28: =IF(D28="—","",IF(D28<=0.33,"🟢",IF(D28<=0.38,"🟡","🔴"))) -> 🟢 | F28: 0.35 | G28: =IF(B28=0,"—",IF(D28<=F28,"🟢 OK","🔴 Excede")) -> 🟢 OK | H28: 4 pers. | I28: Mantener estructura actual
A29: Viernes | B29: {=IFERROR(SUMPRODUCT((WEEKDAY('Facturación 2026'!$A$4:$A$253,2)=5)*'Facturación 2026'!$F$4:$F$253)/SUMPRODUCT((WEEKDAY('Facturación 2026'!$A$4:$A$253,2)=5)*('Facturación 2026'!$F$4:$F$253>0)*1),0)} -> 1390.5263 | C29: {=IFERROR(SUMPRODUCT((WEEKDAY('Facturación 2026'!$A$4:$A$253,2)=5)*'Facturación 2026'!$J$4:$J$253)/SUMPRODUCT((WEEKDAY('Facturación 2026'!$A$4:$A$253,2)=5)*('Facturación 2026'!$F$4:$F$253>0)*1),0)} -> 364.64172 | D29: =IFERROR(C29/B29,"—") -> 0.26223288 | E29: =IF(D29="—","",IF(D29<=0.33,"🟢",IF(D29<=0.38,"🟡","🔴"))) -> 🟢 | F29: 0.32 | G29: =IF(B29=0,"—",IF(D29<=F29,"🟢 OK","🔴 Excede")) -> 🟢 OK | H29: 5 pers. | I29: Reforzar noche esp. en eventos Casino
A30: Sábado | B30: {=IFERROR(SUMPRODUCT((WEEKDAY('Facturación 2026'!$A$4:$A$253,2)=6)*'Facturación 2026'!$F$4:$F$253)/SUMPRODUCT((WEEKDAY('Facturación 2026'!$A$4:$A$253,2)=6)*('Facturación 2026'!$F$4:$F$253>0)*1),0)} -> 2217.3901 | C30: {=IFERROR(SUMPRODUCT((WEEKDAY('Facturación 2026'!$A$4:$A$253,2)=6)*'Facturación 2026'!$J$4:$J$253)/SUMPRODUCT((WEEKDAY('Facturación 2026'!$A$4:$A$253,2)=6)*('Facturación 2026'!$F$4:$F$253>0)*1),0)} -> 406.70617 | D30: =IFERROR(C30/B30,"—") -> 0.1834166 | E30: =IF(D30="—","",IF(D30<=0.33,"🟢",IF(D30<=0.38,"🟡","🔴"))) -> 🟢 | F30: 0.3 | G30: =IF(B30=0,"—",IF(D30<=F30,"🟢 OK","🔴 Excede")) -> 🟢 OK | H30: 6 pers. | I30: Día más rentable — maximizar ocupación
A31: Domingo | B31: {=IFERROR(SUMPRODUCT((WEEKDAY('Facturación 2026'!$A$4:$A$253,2)=7)*'Facturación 2026'!$F$4:$F$253)/SUMPRODUCT((WEEKDAY('Facturación 2026'!$A$4:$A$253,2)=7)*('Facturación 2026'!$F$4:$F$253>0)*1),0)} -> 1485.3766 | C31: {=IFERROR(SUMPRODUCT((WEEKDAY('Facturación 2026'!$A$4:$A$253,2)=7)*'Facturación 2026'!$J$4:$J$253)/SUMPRODUCT((WEEKDAY('Facturación 2026'!$A$4:$A$253,2)=7)*('Facturación 2026'!$F$4:$F$253>0)*1),0)} -> 312.65917 | D31: =IFERROR(C31/B31,"—") -> 0.21049151 | E31: =IF(D31="—","",IF(D31<=0.33,"🟢",IF(D31<=0.38,"🟡","🔴"))) -> 🟢 | F31: 0.33 | G31: =IF(B31=0,"—",IF(D31<=F31,"🟢 OK","🔴 Excede")) -> 🟢 OK | H31: 5 pers. | I31: Noche nueva desde abril — monitorizar
A32: Lunes | B32: {=IFERROR(SUMPRODUCT((WEEKDAY('Facturación 2026'!$A$4:$A$253,2)=1)*'Facturación 2026'!$F$4:$F$253)/SUMPRODUCT((WEEKDAY('Facturación 2026'!$A$4:$A$253,2)=1)*('Facturación 2026'!$F$4:$F$253>0)*1),0)} -> 0 | C32: {=IFERROR(SUMPRODUCT((WEEKDAY('Facturación 2026'!$A$4:$A$253,2)=1)*'Facturación 2026'!$J$4:$J$253)/SUMPRODUCT((WEEKDAY('Facturación 2026'!$A$4:$A$253,2)=1)*('Facturación 2026'!$F$4:$F$253>0)*1),0)} -> 0 | D32: =IFERROR(C32/B32,"—") -> — | E32: =IF(D32="—","",IF(D32<=0.33,"🟢",IF(D32<=0.38,"🟡","🔴"))) | G32: =IF(B32=0,"—",IF(D32<=F32,"🟢 OK","🔴 Excede")) -> — | H32: — | I32: Cierre programado
A33: Martes | B33: {=IFERROR(SUMPRODUCT((WEEKDAY('Facturación 2026'!$A$4:$A$253,2)=2)*'Facturación 2026'!$F$4:$F$253)/SUMPRODUCT((WEEKDAY('Facturación 2026'!$A$4:$A$253,2)=2)*('Facturación 2026'!$F$4:$F$253>0)*1),0)} -> 0 | C33: {=IFERROR(SUMPRODUCT((WEEKDAY('Facturación 2026'!$A$4:$A$253,2)=2)*'Facturación 2026'!$J$4:$J$253)/SUMPRODUCT((WEEKDAY('Facturación 2026'!$A$4:$A$253,2)=2)*('Facturación 2026'!$F$4:$F$253>0)*1),0)} -> 0 | D33: =IFERROR(C33/B33,"—") -> — | E33: =IF(D33="—","",IF(D33<=0.33,"🟢",IF(D33<=0.38,"🟡","🔴"))) | G33: =IF(B33=0,"—",IF(D33<=F33,"🟢 OK","🔴 Excede")) -> — | H33: — | I33: Cierre programado
A36: COSTES DE PERSONAL — TOP EMPLEADOS (ene–abr 2026 corregido)
A37: Empleado | B37: €/hora | C37: Total € | D37: % s/masa | E37: Coste/€vendido | F37: Turno principal | G37: Días semana | H37: Nota gerencia
A38: ='Resumen Empleado'!A4 -> Sonia | B38: ='Resumen Empleado'!B4 -> 16 | C38: {=SUMPRODUCT(('Horarios Personal'!$D$5:$D$816='Resumen Empleado'!A4)*IFERROR('Horarios Personal'!$L$5:$L$816*1,0))} -> 10981.333 | D38: =IFERROR(C38/SUM(C38:C43),0) -> 0.40103832 | E38: =IFERROR(C38/'Facturación 2026'!P16,0) -> 0.10425381 | F38: Todos los turnos | G38: Mié–Dom | H38: Mayor coste unit. — alta productividad domingos
A39: ='Resumen Empleado'!A5 -> Lourdes | B39: ='Resumen Empleado'!B5 -> 10 | C39: {=SUMPRODUCT(('Horarios Personal'!$D$5:$D$816='Resumen Empleado'!A5)*IFERROR('Horarios Personal'!$L$5:$L$816*1,0))} -> 6740 | D39: =IFERROR(C39/SUM(C38:C43),0) -> 0.24614482 | E39: =IFERROR(C39/'Facturación 2026'!P16,0) -> 0.06398774 | F39: Mañana/split | G39: Mié–Dom | H39: Versatilidad: MA+NO. Control fichajes splits
A40: ='Resumen Empleado'!A6 -> Mireia M | B40: ='Resumen Empleado'!B6 -> 17.13 | C40: {=SUMPRODUCT(('Horarios Personal'!$D$5:$D$816='Resumen Empleado'!A6)*IFERROR('Horarios Personal'!$L$5:$L$816*1,0))} -> 308.34 | D40: =IFERROR(C40/SUM(C38:C43),0) -> 0.011260578 | E40: =IFERROR(C40/'Facturación 2026'!P16,0) -> 0.0029272967 | F40: Noche fija | G40: Todos | H40: Coste fijo diario (34,26€). Revisar ROI días bajos
A41: ='Resumen Empleado'!A7 -> Alejandra | B41: ='Resumen Empleado'!B7 -> 6.39 | C41: {=SUMPRODUCT(('Horarios Personal'!$D$5:$D$816='Resumen Empleado'!A7)*IFERROR('Horarios Personal'!$L$5:$L$816*1,0))} -> 2317.9725 | D41: =IFERROR(C41/SUM(C38:C43),0) -> 0.084652362 | E41: =IFERROR(C41/'Facturación 2026'!P16,0) -> 0.022006205 | F41: Mañana/Noche | G41: Mié–Dom | H41: Polivalente. Buena relación coste-rendimiento
A42: ='Resumen Empleado'!A8 -> Jonh | B42: ='Resumen Empleado'!B8 -> 7.25 | C42: {=SUMPRODUCT(('Horarios Personal'!$D$5:$D$816='Resumen Empleado'!A8)*IFERROR('Horarios Personal'!$L$5:$L$816*1,0))} -> 4605.5675 | D42: =IFERROR(C42/SUM(C38:C43),0) -> 0.16819534 | E42: =IFERROR(C42/'Facturación 2026'!P16,0) -> 0.043724015 | F42: Mediodía/Noche | G42: Mié–Dom | H42: Buen perfil noche. Ampliable en alta temporada
A43: ='Resumen Empleado'!A9 -> Rubí | B43: ='Resumen Empleado'!B9 -> 5.17 | C43: {=SUMPRODUCT(('Horarios Personal'!$D$5:$D$816='Resumen Empleado'!A9)*IFERROR('Horarios Personal'!$L$5:$L$816*1,0))} -> 2429.0408 | D43: =IFERROR(C43/SUM(C38:C43),0) -> 0.088708578 | E43: =IFERROR(C43/'Facturación 2026'!P16,0) -> 0.023060658 | F43: Mañana | G43: Mié–Dom | H43: Perfil mañana — revisar disponibilidad verano
A46: ALERTAS OPERATIVAS Y CHECKLIST DE GERENCIA
B47: Prioridad | C47: Concepto | D47: Detalle / Acción
A48: ⚡ | B48: URGENTE | D48: 26/04/2026 — Joan Pera Casino | G48: Confirmado · Reforzar turno noche: +1 sala +1 barra · Prev. 2.800€
...

Sheet Arqueo e incentivos
K4: 2025 | M4: 2026
K5: 5 - 7 Mercado de Navidad
K7: 27-05 carnaval | M7: 12-18 carnaval
I8: segunda quincena | K8: 18-26 fem bullir | M8: 16 - 22 fem bullir
K9: 14 - 21 semana santa | M9: 29 - 06 semana santa
K10: 05-12 escaldarium
K11: 11-18 Fiesta mayor | S11: -27177.279
L14: 30243.025
G17: Incremento IPC | H17: 0.03 | J17: Mes | K17: Ventas 2025 | L17: Previsión | M17: Ventas 2026 | N17: % sobre 24 | O17: Diferencia | P17: Días Trabajados | Q17: In Ven/Dia | R17: Hasta objetivo | S17: Incentivo | T17: Efectivo
G18: Incentivos | H18: 0.1 | J18: Enero | K18: 22382.26 | L18: =K18*H$17+K18 -> 23053.728 | M18: =SUMIFS($P:$P,$D:$D,">="&DATE(2026,MATCH(LOWER(J18),{"enero","febrero","marzo","abril","mayo","junio","julio","agosto","septiembre","octubre","noviembre","diciembre"},0),1),$D:$D,"<"&DATE(2026,MATCH(LOWER(J18),{"enero","febrero","marzo","abril","mayo","junio","julio","agosto","septiembre","octubre","noviembre","diciembre"},0)+1,1)) -> 25876.455 | N18: =-1+M18/K18 -> 0.15611447 | O18: =L18-K18 -> 671.4678 | P18: 23 | Q18: =O18/P18 -> 29.194252 | R18: =M18-L18 -> 2822.7267 | S18: =Tabla14[[#This Row],[Hasta objetivo]]*H$18 -> 282.27267 | T18: =SUMIFS($F:$F,$D:$D,">="&DATE(2026,MATCH(LOWER(J18),{"enero","febrero","marzo","abril","mayo","junio","julio","agosto","septiembre","octubre","noviembre","diciembre"},0),1),$D:$D,"<"&DATE(2026,MATCH(LOWER(J18),{"enero","febrero","marzo","abril","mayo","junio","julio","agosto","septiembre","octubre","noviembre","diciembre"},0)+1,1)) -> 3139
J19: Febrero | K19: 22499.24 | L19: =K19*H$17+K19 -> 23174.217 | M19: =SUMIFS($P:$P,$D:$D,">="&DATE(2026,MATCH(LOWER(J19),{"enero","febrero","marzo","abril","mayo","junio","julio","agosto","septiembre","octubre","noviembre","diciembre"},0),1),$D:$D,"<"&DATE(2026,MATCH(LOWER(J19),{"enero","febrero","marzo","abril","mayo","junio","julio","agosto","septiembre","octubre","noviembre","diciembre"},0)+1,1)) -> 26984.915 | N19: =-1+M19/K19 -> 0.19937009 | O19: 674.98 | P19: 16 | Q19: =O19/P19 -> 42.18625 | R19: =M19-L19 -> 3810.6983 | S19: =Tabla14[[#This Row],[Hasta objetivo]]*H$18 -> 381.06983 | T19: =SUMIFS($F:$F,$D:$D,">="&DATE(2026,MATCH(LOWER(J19),{"enero","febrero","marzo","abril","mayo","junio","julio","agosto","septiembre","octubre","noviembre","diciembre"},0),1),$D:$D,"<"&DATE(2026,MATCH(LOWER(J19),{"enero","febrero","marzo","abril","mayo","junio","julio","agosto","septiembre","octubre","noviembre","diciembre"},0)+1,1)) -> 4526.17
E20: Saldo anterior 2025 | G20: =[1]Hoja10!$G$22 -> 5530.1213 | J20: Marzo | K20: 21443.45 | L20: =K20*H$17+K20 -> 22086.753 | M20: =SUMIFS($P:$P,$D:$D,">="&DATE(2026,MATCH(LOWER(J20),{"enero","febrero","marzo","abril","mayo","junio","julio","agosto","septiembre","octubre","noviembre","diciembre"},0),1),$D:$D,"<"&DATE(2026,MATCH(LOWER(J20),{"enero","febrero","marzo","abril","mayo","junio","julio","agosto","septiembre","octubre","noviembre","diciembre"},0)+1,1)) -> 19903.077 | N20: =-1+M20/K20 -> -0.071834184 | O20: 643.3 | P20: 15 | Q20: =O20/P20 -> 42.886667 | R20: =M20-L20 -> -2183.6762 | S20: =Tabla14[[#This Row],[Hasta objetivo]]*H$18 -> -218.36762 | T20: =SUMIFS($F:$F,$D:$D,">="&DATE(2026,MATCH(LOWER(J20),{"enero","febrero","marzo","abril","mayo","junio","julio","agosto","septiembre","octubre","noviembre","diciembre"},0),1),$D:$D,"<"&DATE(2026,MATCH(LOWER(J20),{"enero","febrero","marzo","abril","mayo","junio","julio","agosto","septiembre","octubre","noviembre","diciembre"},0)+1,1)) -> 3494.85
E21: Arrastre efectivo | G21: =SUM(Tabla15[Ingreso]) -> 13048.68 | J21: Abril | K21: 31530.01 | L21: =K21*H$17+K21 -> 32475.91 | M21: =SUMIFS($P:$P,$D:$D,">="&DATE(2026,MATCH(LOWER(J21),{"enero","febrero","marzo","abril","mayo","junio","julio","agosto","septiembre","octubre","noviembre","diciembre"},0),1),$D:$D,"<"&DATE(2026,MATCH(LOWER(J21),{"enero","febrero","marzo","abril","mayo","junio","julio","agosto","septiembre","octubre","noviembre","diciembre"},0)+1,1)) -> 30141.918 | N21: =-1+M21/K21 -> -0.044024465 | O21: 945.9 | P21: 22 | Q21: =O21/P21 -> 42.995455 | R21: =M21-L21 -> -2333.9921 | S21: =Tabla14[[#This Row],[Hasta objetivo]]*H$18 -> -233.39921 | T21: =SUMIFS($F:$F,$D:$D,">="&DATE(2026,MATCH(LOWER(J21),{"enero","febrero","marzo","abril","mayo","junio","julio","agosto","septiembre","octubre","noviembre","diciembre"},0),1),$D:$D,"<"&DATE(2026,MATCH(LOWER(J21),{"enero","febrero","marzo","abril","mayo","junio","julio","agosto","septiembre","octubre","noviembre","diciembre"},0)+1,1)) -> 5390.6
E22: Ingresado Bbva | G22: 0 | J22: Mayo | K22: 29362.16 | L22: =K22*H$17+K22 -> 30243.025 | M22: =SUMIFS($P:$P,$D:$D,">="&DATE(2026,MATCH(LOWER(J22),{"enero","febrero","marzo","abril","mayo","junio","julio","agosto","septiembre","octubre","noviembre","diciembre"},0),1),$D:$D,"<"&DATE(2026,MATCH(LOWER(J22),{"enero","febrero","marzo","abril","mayo","junio","julio","agosto","septiembre","octubre","noviembre","diciembre"},0)+1,1)) -> 3065.7455 | N22: =-1+M22/K22 -> -0.89558856 | O22: 880.86 | P22: 23 | Q22: =O22/P22 -> 38.298261 | R22: =M22-L22 -> -27177.279 | S22: =Tabla14[[#This Row],[Hasta objetivo]]*H$18 -> -2717.7279 | T22: =SUMIFS($F:$F,$D:$D,">="&DATE(2026,MATCH(LOWER(J22),{"enero","febrero","marzo","abril","mayo","junio","julio","agosto","septiembre","octubre","noviembre","diciembre"},0),1),$D:$D,"<"&DATE(2026,MATCH(LOWER(J22),{"enero","febrero","marzo","abril","mayo","junio","julio","agosto","septiembre","octubre","noviembre","diciembre"},0)+1,1)) -> 77.7
G23: =G20+G21-G22 -> 18578.801 | J23: Junio | K23: 33832.98 | L23: =K23*H$17+K23 -> 34847.969 | M23: =SUMIFS($P:$P,$D:$D,">="&DATE(2026,MATCH(LOWER(J23),{"enero","febrero","marzo","abril","mayo","junio","julio","agosto","septiembre","octubre","noviembre","diciembre"},0),1),$D:$D,"<"&DATE(2026,MATCH(LOWER(J23),{"enero","febrero","marzo","abril","mayo","junio","julio","agosto","septiembre","octubre","noviembre","diciembre"},0)+1,1)) -> 0 | N23: =-1+M23/K23 -> -1 | O23: 1014.99 | P23: 20 | Q23: =O23/P23 -> 50.7495 | R23: =M23-L23 -> -34847.969 | S23: =Tabla14[[#This Row],[Hasta objetivo]]*H$18 -> -3484.7969 | T23: =SUMIFS($F:$F,$D:$D,">="&DATE(2026,MATCH(LOWER(J23),{"enero","febrero","marzo","abril","mayo","junio","julio","agosto","septiembre","octubre","noviembre","diciembre"},0),1),$D:$D,"<"&DATE(2026,MATCH(LOWER(J23),{"enero","febrero","marzo","abril","mayo","junio","julio","agosto","septiembre","octubre","noviembre","diciembre"},0)+1,1)) -> 0
J24: Julio | K24: 32495.01 | L24: =K24*H$17+K24 -> 33469.86 | M24: =SUMIFS($P:$P,$D:$D,">="&DATE(2026,MATCH(LOWER(J24),{"enero","febrero","marzo","abril","mayo","junio","julio","agosto","septiembre","octubre","noviembre","diciembre"},0),1),$D:$D,"<"&DATE(2026,MATCH(LOWER(J24),{"enero","febrero","marzo","abril","mayo","junio","julio","agosto","septiembre","octubre","noviembre","diciembre"},0)+1,1)) -> 0 | N24: =-1+M24/K24 -> -1 | O24: 974.85 | P24: 23 | Q24: =O24/P24 -> 42.384783 | R24: =M24-L24 -> -33469.86 | S24: =Tabla14[[#This Row],[Hasta objetivo]]*H$18 -> -3346.986 | T24: =SUMIFS($F:$F,$D:$D,">="&DATE(2026,MATCH(LOWER(J24),{"enero","febrero","marzo","abril","mayo","junio","julio","agosto","septiembre","octubre","noviembre","diciembre"},0),1),$D:$D,"<"&DATE(2026,MATCH(LOWER(J24),{"enero","febrero","marzo","abril","mayo","junio","julio","agosto","septiembre","octubre","noviembre","diciembre"},0)+1,1)) -> 0
J25: Agosto | K25: 43459.73 | L25: =K25*H$17+K25 -> 44763.522 | M25: =SUMIFS($P:$P,$D:$D,">="&DATE(2026,MATCH(LOWER(J25),{"enero","febrero","marzo","abril","mayo","junio","julio","agosto","septiembre","octubre","noviembre","diciembre"},0),1),$D:$D,"<"&DATE(2026,MATCH(LOWER(J25),{"enero","febrero","marzo","abril","mayo","junio","julio","agosto","septiembre","octubre","noviembre","diciembre"},0)+1,1)) -> 0 | N25: =-1+M25/K25 -> -1 | O25: 1303.79 | P25: 22 | Q25: =O25/P25 -> 59.263182 | R25: =M25-L25 -> -44763.522 | S25: =Tabla14[[#This Row],[Hasta objetivo]]*H$18 -> -4476.3522 | T25: =SUMIFS($F:$F,$D:$D,">="&DATE(2026,MATCH(LOWER(J25),{"enero","febrero","marzo","abril","mayo","junio","julio","agosto","septiembre","octubre","noviembre","diciembre"},0),1),$D:$D,"<"&DATE(2026,MATCH(LOWER(J25),{"enero","febrero","marzo","abril","mayo","junio","julio","agosto","septiembre","octubre","noviembre","diciembre"},0)+1,1)) -> 0
J26: Septiembre | K26: 27943.16 | L26: =K26*H$17+K26 -> 28781.455 | M26: =SUMIFS($P:$P,$D:$D,">="&DATE(2026,MATCH(LOWER(J26),{"enero","febrero","marzo","abril","mayo","junio","julio","agosto","septiembre","octubre","noviembre","diciembre"},0),1),$D:$D,"<"&DATE(2026,MATCH(LOWER(J26),{"enero","febrero","marzo","abril","mayo","junio","julio","agosto","septiembre","octubre","noviembre","diciembre"},0)+1,1)) -> 0 | N26: =-1+M26/K26 -> -1 | O26: 838.29 | P26: 21 | Q26: =O26/P26 -> 39.918571 | R26: =M26-L26 -> -28781.455 | S26: =Tabla14[[#This Row],[Hasta objetivo]]*H$18 -> -2878.1455 | T26: =SUMIFS($F:$F,$D:$D,">="&DATE(2026,MATCH(LOWER(J26),{"enero","febrero","marzo","abril","mayo","junio","julio","agosto","septiembre","octubre","noviembre","diciembre"},0),1),$D:$D,"<"&DATE(2026,MATCH(LOWER(J26),{"enero","febrero","marzo","abril","mayo","junio","julio","agosto","septiembre","octubre","noviembre","diciembre"},0)+1,1)) -> 0
J27: Octubre | K27: 27843.16 | L27: =K27*H$17+K27 -> 28678.455 | M27: =SUMIFS($P:$P,$D:$D,">="&DATE(2026,MATCH(LOWER(J27),{"enero","febrero","marzo","abril","mayo","junio","julio","agosto","septiembre","octubre","noviembre","diciembre"},0),1),$D:$D,"<"&DATE(2026,MATCH(LOWER(J27),{"enero","febrero","marzo","abril","mayo","junio","julio","agosto","septiembre","octubre","noviembre","diciembre"},0)+1,1)) -> 0 | N27: =-1+M27/K27 -> -1 | O27: 835.29 | P27: 23 | Q27: =O27/P27 -> 36.316957 | R27: =M27-L27 -> -28678.455 | S27: =Tabla14[[#This Row],[Hasta objetivo]]*H$18 -> -2867.8455 | T27: =SUMIFS($F:$F,$D:$D,">="&DATE(2026,MATCH(LOWER(J27),{"enero","febrero","marzo","abril","mayo","junio","julio","agosto","septiembre","octubre","noviembre","diciembre"},0),1),$D:$D,"<"&DATE(2026,MATCH(LOWER(J27),{"enero","febrero","marzo","abril","mayo","junio","julio","agosto","septiembre","octubre","noviembre","diciembre"},0)+1,1)) -> 0
J28: Noviembre | K28: 34247.88 | L28: =K28*H$17+K28 -> 35275.316 | M28: =SUMIFS($P:$P,$D:$D,">="&DATE(2026,MATCH(LOWER(J28),{"enero","febrero","marzo","abril","mayo","junio","julio","agosto","septiembre","octubre","noviembre","diciembre"},0),1),$D:$D,"<"&DATE(2026,MATCH(LOWER(J28),{"enero","febrero","marzo","abril","mayo","junio","julio","agosto","septiembre","octubre","noviembre","diciembre"},0)+1,1)) -> 0 | N28: =-1+M28/K28 -> -1 | O28: 1027.44 | P28: 11 | Q28: =O28/P28 -> 93.403636 | R28: =M28-L28 -> -35275.316 | S28: =Tabla14[[#This Row],[Hasta objetivo]]*H$18 -> -3527.5316 | T28: =SUMIFS($F:$F,$D:$D,">="&DATE(2026,MATCH(LOWER(J28),{"enero","febrero","marzo","abril","mayo","junio","julio","agosto","septiembre","octubre","noviembre","diciembre"},0),1),$D:$D,"<"&DATE(2026,MATCH(LOWER(J28),{"enero","febrero","marzo","abril","mayo","junio","julio","agosto","septiembre","octubre","noviembre","diciembre"},0)+1,1)) -> 0
J29: Diciembre | K29: 36351.3 | L29: =K29*H$17+K29 -> 37441.839 | M29: =SUMIFS($P:$P,$D:$D,">="&DATE(2026,MATCH(LOWER(J29),{"enero","febrero","marzo","abril","mayo","junio","julio","agosto","septiembre","octubre","noviembre","diciembre"},0),1),$D:$D,"<"&DATE(2026,MATCH(LOWER(J29),{"enero","febrero","marzo","abril","mayo","junio","julio","agosto","septiembre","octubre","noviembre","diciembre"},0)+1,1)) -> 0 | N29: =-1+M29/K29 -> -1 | O29: 1090.54 | P29: 17 | Q29: =O29/P29 -> 64.149412 | R29: =M29-L29 -> -37441.839 | S29: =Tabla14[[#This Row],[Hasta objetivo]]*H$18 -> -3744.1839 | T29: =SUMIFS($F:$F,$D:$D,">="&DATE(2026,MATCH(LOWER(J29),{"enero","febrero","marzo","abril","mayo","junio","julio","agosto","septiembre","octubre","noviembre","diciembre"},0),1),$D:$D,"<"&DATE(2026,MATCH(LOWER(J29),{"enero","febrero","marzo","abril","mayo","junio","julio","agosto","septiembre","octubre","noviembre","diciembre"},0)+1,1)) -> 0
D33: Fecha | E33: Contado | F33: Tickets | G33: Visa | H33: Eventos | I33: Passo | J33: Reciclajes | K33: Invitaciones | L33: Personal | M33: Retiros | N33: Ingreso | O33: Bbva | P33: Total Caja | Q33: Efectivo | R33: %Tickets | S33: Columna1 | T33: Facturació A/A | U33: Diferencia | V33: Resto | W33: Dif% | X33: Previsión | Y33: Resultado | Z33: Columna2 | AA33: AA % | AB33: Observaciones
C34: 1 | D34: 46023 | E34: 0 | F34: =Tabla15[[#This Row],[Retiros]]-Tabla15[[#This Row],[Contado]] -> 0 | G34: 0 | H34: 0 | I34: 0 | J34: 0 | K34: 0 | L34: 0 | M34: 0 | N34: =Tabla15[[#This Row],[Contado]] -> 0 | P34: =((Tabla15[[#This Row],[Contado]]+Tabla15[[#This Row],[Visa]]+Tabla15[[#This Row],[Eventos]]+Tabla15[[#This Row],[Passo]]+Tabla15[[#This Row],[Reciclajes]])/1.1)+Tabla15[[#This Row],[Tickets]] -> 0 | Q34: =IFERROR(E34/G34,0) -> 0 | R34: =IFERROR(F34/P34,0) -> 0 | T34: 0 | U34: =Tabla15[[#This Row],[Total Caja]]-Tabla15[[#This Row],[Facturació A/A]] -> 0 | V34: 0 | W34: =Tabla15[[#This Row],[Diferencia]]/Tabla15[[#This Row],[Facturació A/A]] -> #DIV/0! | X34: =Tabla15[[#This Row],[Facturació A/A]]*H$17+Tabla15[[#This Row],[Facturació A/A]] -> 0 | Y34: =Tabla15[[#This Row],[Total Caja]]-Tabla15[[#This Row],[Previsión]] -> 0 | AA34: =SUM(INDEX(Tabla15[[#This Row],[Facturació A/A]],1):Tabla15[[#This Row],[Facturació A/A]]) / SUM(INDEX(Tabla15[[#This Row],[Diferencia]],1):Tabla15[[#This Row],[Diferencia]]) -> #DIV/0! | AB34: lluvias
C35: 2 | D35: 46024 | E35: 133.5 | F35: =Tabla15[[#This Row],[Retiros]]-Tabla15[[#This Row],[Contado]] -> 166.5 | G35: 1442.15 | H35: 0 | I35: 0 | J35: 0 | K35: 0 | L35: 0 | M35: 300 | N35: =Tabla15[[#This Row],[Contado]] -> 133.5 | P35: =((Tabla15[[#This Row],[Contado]]+Tabla15[[#This Row],[Visa]]+Tabla15[[#This Row],[Eventos]]+Tabla15[[#This Row],[Passo]]+Tabla15[[#This Row],[Reciclajes]])/1.1)+Tabla15[[#This Row],[Tickets]] -> 1598.9091 | Q35: 0.09 | R35: =IFERROR(F35/P35,0) -> 0.1041335 | T35: 1848.36 | U35: =Tabla15[[#This Row],[Total Caja]]-Tabla15[[#This Row],[Facturació A/A]] -> -249.45091 | V35: =U35+V34 -> -249.45091 | W35: =Tabla15[[#This Row],[Diferencia]]/Tabla15[[#This Row],[Facturació A/A]] -> -0.13495797 | X35: =Tabla15[[#This Row],[Facturació A/A]]*H$17+Tabla15[[#This Row],[Facturació A/A]] -> 1903.8108 | Y35: =Tabla15[[#This Row],[Total Caja]]-Tabla15[[#This Row],[Previsión]] -> -304.90171 | AA35: =SUM(INDEX(Tabla15[[#This Row],[Facturació A/A]],1):Tabla15[[#This Row],[Facturació A/A]]) / SUM(INDEX(Tabla15[[#This Row],[Diferencia]],1):Tabla15[[#This Row],[Diferencia]]) -> -7.4097144 | AB35: lluvias
C36: 3 | D36: 46025 | E36: 291.35 | F36: =Tabla15[[#This Row],[Retiros]]-Tabla15[[#This Row],[Contado]] -> 98.65 | G36: 1271.95 | H36: 0 | I36: 99.1 | J36: 0 | K36: 0 | L36: 0 | M36: 390 | N36: =Tabla15[[#This Row],[Contado]] -> 291.35 | P36: =((Tabla15[[#This Row],[Contado]]+Tabla15[[#This Row],[Visa]]+Tabla15[[#This Row],[Eventos]]+Tabla15[[#This Row],[Passo]]+Tabla15[[#This Row],[Reciclajes]])/1.1)+Tabla15[[#This Row],[Tickets]] -> 1609.9227 | Q36: 0.23 | R36: =IFERROR(F36/P36,0) -> 0.061276233 | T36: 2277.69 | U36: =Tabla15[[#This Row],[Total Caja]]-Tabla15[[#This Row],[Facturació A/A]] -> -667.76727 | V36: =U36+V35 -> -917.21818 | W36: =Tabla15[[#This Row],[Diferencia]]/Tabla15[[#This Row],[Facturació A/A]] -> -0.29317742 | X36: =Tabla15[[#This Row],[Facturació A/A]]*H$17+Tabla15[[#This Row],[Facturació A/A]] -> 2346.0207 | Y36: =Tabla15[[#This Row],[Total Caja]]-Tabla15[[#This Row],[Previsión]] -> -736.09797 | AA36: =SUM(INDEX(Tabla15[[#This Row],[Facturació A/A]],1):Tabla15[[#This Row],[Facturació A/A]]) / SUM(INDEX(Tabla15[[#This Row],[Diferencia]],1):Tabla15[[#This Row],[Diferencia]]) -> -3.4109039 | AB36: lluvias
C37: 4 | D37: 46026 | E37: 9.75 | F37: =Tabla15[[#This Row],[Retiros]]-Tabla15[[#This Row],[Contado]] -> 80.25 | G37: 940.15 | H37: 0 | I37: 0 | J37: 0 | K37: 0 | L37: 0 | M37: 90 | N37: =Tabla15[[#This Row],[Contado]] -> 9.75 | P37: =((Tabla15[[#This Row],[Contado]]+Tabla15[[#This Row],[Visa]]+Tabla15[[#This Row],[Eventos]]+Tabla15[[#This Row],[Passo]]+Tabla15[[#This Row],[Reciclajes]])/1.1)+Tabla15[[#This Row],[Tickets]] -> 943.79545 | Q37: 0.01 | R37: =IFERROR(F37/P37,0) -> 0.085029017 | T37: 1352.24 | U37: =Tabla15[[#This Row],[Total Caja]]-Tabla15[[#This Row],[Facturació A/A]] -> -408.44455 | V37: =U37+V36 -> -1325.6627 | W37: =Tabla15[[#This Row],[Diferencia]]/Tabla15[[#This Row],[Facturació A/A]] -> -0.30205034 | X37: =Tabla15[[#This Row],[Facturació A/A]]*H$17+Tabla15[[#This Row],[Facturació A/A]] -> 1392.8072 | Y37: =Tabla15[[#This Row],[Total Caja]]-Tabla15[[#This Row],[Previsión]] -> -449.01175 | AA37: =SUM(INDEX(Tabla15[[#This Row],[Facturació A/A]],1):Tabla15[[#This Row],[Facturació A/A]]) / SUM(INDEX(Tabla15[[#This Row],[Diferencia]],1):Tabla15[[#This Row],[Diferencia]]) -> -3.3107065 | AB37: lluvias
C38: 5 | D38: 46027 | E38: 0 | F38: =Tabla15[[#This Row],[Retiros]]-Tabla15[[#This Row],[Contado]] -> 0 | G38: 0 | H38: 0 | I38: 0 | J38: 0 | K38: 0 | L38: 0 | M38: 0 | N38: =Tabla15[[#This Row],[Contado]] -> 0 | P38: =((Tabla15[[#This Row],[Contado]]+Tabla15[[#This Row],[Visa]]+Tabla15[[#This Row],[Eventos]]+Tabla15[[#This Row],[Passo]]+Tabla15[[#This Row],[Reciclajes]])/1.1)+Tabla15[[#This Row],[Tickets]] -> 0 | Q38: 0 | R38: =IFERROR(F38/P38,0) -> 0 | T38: 0 | U38: =Tabla15[[#This Row],[Total Caja]]-Tabla15[[#This Row],[Facturació A/A]] -> 0 | V38: =U38+V37 -> -1325.6627 | W38: =Tabla15[[#This Row],[Diferencia]]/Tabla15[[#This Row],[Facturació A/A]] -> #DIV/0! | X38: =Tabla15[[#This Row],[Facturació A/A]]*H$17+Tabla15[[#This Row],[Facturació A/A]] -> 0 | Y38: =Tabla15[[#This Row],[Total Caja]]-Tabla15[[#This Row],[Previsión]] -> 0 | AA38: =SUM(INDEX(Tabla15[[#This Row],[Facturació A/A]],1):Tabla15[[#This Row],[Facturació A/A]]) / SUM(INDEX(Tabla15[[#This Row],[Diferencia]],1):Tabla15[[#This Row],[Diferencia]]) -> #DIV/0! | AB38: lluvias
C39: 6 | D39: 46028 | E39: 0 | F39: =Tabla15[[#This Row],[Retiros]]-Tabla15[[#This Row],[Contado]] -> 0 | G39: 0 | H39: 0 | I39: 0 | J39: 0 | K39: 0 | L39: 0 | M39: 0 | N39: =Tabla15[[#This Row],[Contado]] -> 0 | P39: =((Tabla15[[#This Row],[Contado]]+Tabla15[[#This Row],[Visa]]+Tabla15[[#This Row],[Eventos]]+Tabla15[[#This Row],[Passo]]+Tabla15[[#This Row],[Reciclajes]])/1.1)+Tabla15[[#This Row],[Tickets]] -> 0 | Q39: 0 | R39: =IFERROR(F39/P39,0) -> 0 | T39: 0 | U39: =Tabla15[[#This Row],[Total Caja]]-Tabla15[[#This Row],[Facturació A/A]] -> 0 | V39: =U39+V38 -> -1325.6627 | W39: =Tabla15[[#This Row],[Diferencia]]/Tabla15[[#This Row],[Facturació A/A]] -> #DIV/0! | X39: =Tabla15[[#This Row],[Facturació A/A]]*H$17+Tabla15[[#This Row],[Facturació A/A]] -> 0 | Y39: =Tabla15[[#This Row],[Total Caja]]-Tabla15[[#This Row],[Previsión]] -> 0 | AA39: =SUM(INDEX(Tabla15[[#This Row],[Facturació A/A]],1):Tabla15[[#This Row],[Facturació A/A]]) / SUM(INDEX(Tabla15[[#This Row],[Diferencia]],1):Tabla15[[#This Row],[Diferencia]]) -> #DIV/0! | AB39: lluvias
C40: 7 | D40: 46029 | E40: 26 | F40: =Tabla15[[#This Row],[Retiros]]-Tabla15[[#This Row],[Contado]] -> 194 | G40: 361.5 | H40: 0 | I40: 39.35 | J40: 0 | K40: 0 | L40: 0 | M40: 220 | N40: =Tabla15[[#This Row],[Contado]] -> 26 | P40: =((Tabla15[[#This Row],[Contado]]+Tabla15[[#This Row],[Visa]]+Tabla15[[#This Row],[Eventos]]+Tabla15[[#This Row],[Passo]]+Tabla15[[#This Row],[Reciclajes]])/1.1)+Tabla15[[#This Row],[Tickets]] -> 582.04545 | Q40: 0.07 | R40: =IFERROR(F40/P40,0) -> 0.3333073 | T40: 322.79 | U40: =Tabla15[[#This Row],[Total Caja]]-Tabla15[[#This Row],[Facturació A/A]] -> 259.25545 | V40: =U40+V39 -> -1066.4073 | W40: =Tabla15[[#This Row],[Diferencia]]/Tabla15[[#This Row],[Facturació A/A]] -> 0.80317065 | X40: =Tabla15[[#This Row],[Facturació A/A]]*H$17+Tabla15[[#This Row],[Facturació A/A]] -> 332.4737 | Y40: =Tabla15[[#This Row],[Total Caja]]-Tabla15[[#This Row],[Previsión]] -> 249.57175 | AA40: =SUM(INDEX(Tabla15[[#This Row],[Facturació A/A]],1):Tabla15[[#This Row],[Facturació A/A]]) / SUM(INDEX(Tabla15[[#This Row],[Diferencia]],1):Tabla15[[#This Row],[Diferencia]]) -> 1.2450654 | AB40: lluvias
C41: 8 | D41: 46030 | E41: 0 | F41: =Tabla15[[#This Row],[Retiros]]-Tabla15[[#This Row],[Contado]] -> 243 | G41: 505.1 | H41: 0 | I41: 0 | J41: 0 | K41: 0 | L41: 0 | M41: 243 | N41: =Tabla15[[#This Row],[Contado]] -> 0 | P41: =((Tabla15[[#This Row],[Contado]]+Tabla15[[#This Row],[Visa]]+Tabla15[[#This Row],[Eventos]]+Tabla15[[#This Row],[Passo]]+Tabla15[[#This Row],[Reciclajes]])/1.1)+Tabla15[[#This Row],[Tickets]] -> 702.18182 | Q41: 0 | R41: =IFERROR(F41/P41,0) -> 0.34606422 | T41: 481.23 | U41: =Tabla15[[#This Row],[Total Caja]]-Tabla15[[#This Row],[Facturació A/A]] -> 220.95182 | V41: =U41+V40 -> -845.45545 | W41: =Tabla15[[#This Row],[Diferencia]]/Tabla15[[#This Row],[Facturació A/A]] -> 0.45913974 | X41: =Tabla15[[#This Row],[Facturació A/A]]*H$17+Tabla15[[#This Row],[Facturació A/A]] -> 495.6669 | Y41: =Tabla15[[#This Row],[Total Caja]]-Tabla15[[#This Row],[Previsión]] -> 206.51492 | AA41: =SUM(INDEX(Tabla15[[#This Row],[Facturació A/A]],1):Tabla15[[#This Row],[Facturació A/A]]) / SUM(INDEX(Tabla15[[#This Row],[Diferencia]],1):Tabla15[[#This Row],[Diferencia]]) -> 2.1779862 | AB41: lluvias
C42: 9 | D42: 46031 | E42: 153.15 | F42: =Tabla15[[#This Row],[Retiros]]-Tabla15[[#This Row],[Contado]] -> 216.85 | G42: 681.7 | H42: 0 | I42: 0 | J42: 0 | K42: 0 | L42: 0 | M42: 370 | N42: =Tabla15[[#This Row],[Contado]] -> 153.15 | P42: =((Tabla15[[#This Row],[Contado]]+Tabla15[[#This Row],[Visa]]+Tabla15[[#This Row],[Eventos]]+Tabla15[[#This Row],[Passo]]+Tabla15[[#This Row],[Reciclajes]])/1.1)+Tabla15[[#This Row],[Tickets]] -> 975.80455 | Q42: 0.22 | R42: =IFERROR(F42/P42,0) -> 0.22222688 | T42: 950.95 | U42: =Tabla15[[#This Row],[Total Caja]]-Tabla15[[#This Row],[Facturació A/A]] -> 24.854545 | V42: =U42+V41 -> -820.60091 | W42: =Tabla15[[#This Row],[Diferencia]]/Tabla15[[#This Row],[Facturació A/A]] -> 0.026136543 | X42: =Tabla15[[#This Row],[Facturació A/A]]*H$17+Tabla15[[#This Row],[Facturació A/A]] -> 979.4785 | Y42: =Tabla15[[#This Row],[Total Caja]]-Tabla15[[#This Row],[Previsión]] -> -3.6739545 | AA42: =SUM(INDEX(Tabla15[[#This Row],[Facturació A/A]],1):Tabla15[[#This Row],[Facturació A/A]]) / SUM(INDEX(Tabla15[[#This Row],[Diferencia]],1):Tabla15[[#This Row],[Diferencia]]) -> 38.260607 | AB42: lluvias
C43: 10 | D43: 46032 | E43: 595.7 | F43: =Tabla15[[#This Row],[Retiros]]-Tabla15[[#This Row],[Contado]] -> 129.3 | G43: 1886.65 | H43: 0 | I43: 50.55 | J43: 0 | K43: 0 | L43: 0 | M43: 725 | N43: =Tabla15[[#This Row],[Contado]] -> 595.7 | P43: =((Tabla15[[#This Row],[Contado]]+Tabla15[[#This Row],[Visa]]+Tabla15[[#This Row],[Eventos]]+Tabla15[[#This Row],[Passo]]+Tabla15[[#This Row],[Reciclajes]])/1.1)+Tabla15[[#This Row],[Tickets]] -> 2431.9364 | Q43: 0.32 | R43: =IFERROR(F43/P43,0) -> 0.05316751 | T43: 1330.08 | U43: =Tabla15[[#This Row],[Total Caja]]-Tabla15[[#This Row],[Facturació A/A]] -> 1101.8564 | V43: =U43+V42 -> 281.25545 | W43: =Tabla15[[#This Row],[Diferencia]]/Tabla15[[#This Row],[Facturació A/A]] -> 0.8284136 | X43: =Tabla15[[#This Row],[Facturació A/A]]*H$17+Tabla15[[#This Row],[Facturació A/A]] -> 1369.9824 | Y43: =Tabla15[[#This Row],[Total Caja]]-Tabla15[[#This Row],[Previsión]] -> 1061.954 | AA43: =SUM(INDEX(Tabla15[[#This Row],[Facturació A/A]],1):Tabla15[[#This Row],[Facturació A/A]]) / SUM(INDEX(Tabla15[[#This Row],[Diferencia]],1):Tabla15[[#This Row],[Diferencia]]) -> 1.2071265 | AB43: lluvias
C44: 11 | D44: 46033 | E44: 217.15 | F44: =Tabla15[[#This Row],[Retiros]]-Tabla15[[#This Row],[Contado]] -> 77.85 | G44: 596 | H44: 0 | I44: 53.25 | J44: 0 | K44: 0 | L44: 0 | M44: 295 | N44: =Tabla15[[#This Row],[Contado]] -> 217.15 | P44: =((Tabla15[[#This Row],[Contado]]+Tabla15[[#This Row],[Visa]]+Tabla15[[#This Row],[Eventos]]+Tabla15[[#This Row],[Passo]]+Tabla15[[#This Row],[Reciclajes]])/1.1)+Tabla15[[#This Row],[Tickets]] -> 865.48636 | Q44: 0.36 | R44: =IFERROR(F44/P44,0) -> 0.089949424 | T44: 1023.71 | U44: =Tabla15[[#This Row],[Total Caja]]-Tabla15[[#This Row],[Facturació A/A]] -> -158.22364 | V44: =U44+V43 -> 123.03182 | W44: =Tabla15[[#This Row],[Diferencia]]/Tabla15[[#This Row],[Facturació A/A]] -> -0.15455904 | X44: =Tabla15[[#This Row],[Facturació A/A]]*H$17+Tabla15[[#This Row],[Facturació A/A]] -> 1054.4213 | Y44: =Tabla15[[#This Row],[Total Caja]]-Tabla15[[#This Row],[Previsión]] -> -188.93494 | AA44: =SUM(INDEX(Tabla15[[#This Row],[Facturació A/A]],1):Tabla15[[#This Row],[Facturació A/A]]) / SUM(INDEX(Tabla15[[#This Row],[Diferencia]],1):Tabla15[[#This Row],[Diferencia]]) -> -6.4700194 | AB44: lluvias
C45: 12 | D45: 46034 | E45: 0 | F45: =Tabla15[[#This Row],[Retiros]]-Tabla15[[#This Row],[Contado]] -> 0 | G45: 0 | H45: 0 | I45: 0 | J45: 0 | K45: 0 | L45: 0 | M45: 0 | N45: =Tabla15[[#This Row],[Contado]] -> 0 | P45: =((Tabla15[[#This Row],[Contado]]+Tabla15[[#This Row],[Visa]]+Tabla15[[#This Row],[Eventos]]+Tabla15[[#This Row],[Passo]]+Tabla15[[#This Row],[Reciclajes]])/1.1)+Tabla15[[#This Row],[Tickets]] -> 0 | Q45: 0 | R45: =IFERROR(F45/P45,0) -> 0 | T45: 0 | U45: =Tabla15[[#This Row],[Total Caja]]-Tabla15[[#This Row],[Facturació A/A]] -> 0 | V45: =U45+V44 -> 123.03182 | W45: =Tabla15[[#This Row],[Diferencia]]/Tabla15[[#This Row],[Facturació A/A]] -> #DIV/0! | X45: =Tabla15[[#This Row],[Facturació A/A]]*H$17+Tabla15[[#This Row],[Facturació A/A]] -> 0 | Y45: =Tabla15[[#This Row],[Total Caja]]-Tabla15[[#This Row],[Previsión]] -> 0 | AA45: =SUM(INDEX(Tabla15[[#This Row],[Facturació A/A]],1):Tabla15[[#This Row],[Facturació A/A]]) / SUM(INDEX(Tabla15[[#This Row],[Diferencia]],1):Tabla15[[#This Row],[Diferencia]]) -> #DIV/0! | AB45: lluvias
C46: 13 | D46: 46035 | E46: 0 | F46: =Tabla15[[#This Row],[Retiros]]-Tabla15[[#This Row],[Contado]] -> 0 | G46: 0 | H46: 0 | I46: 0 | J46: 0 | K46: 0 | L46: 0 | M46: 0 | N46: =Tabla15[[#This Row],[Contado]] -> 0 | P46: =((Tabla15[[#This Row],[Contado]]+Tabla15[[#This Row],[Visa]]+Tabla15[[#This Row],[Eventos]]+Tabla15[[#This Row],[Passo]]+Tabla15[[#This Row],[Reciclajes]])/1.1)+Tabla15[[#This Row],[Tickets]] -> 0 | Q46: 0 | R46: =IFERROR(F46/P46,0) -> 0 | T46: 0 | U46: =Tabla15[[#This Row],[Total Caja]]-Tabla15[[#This Row],[Facturació A/A]] -> 0 | V46: =U46+V45 -> 123.03182 | W46: =Tabla15[[#This Row],[Diferencia]]/Tabla15[[#This Row],[Facturació A/A]] -> #DIV/0! | X46: =Tabla15[[#This Row],[Facturació A/A]]*H$17+Tabla15[[#This Row],[Facturació A/A]] -> 0 | Y46: =Tabla15[[#This Row],[Total Caja]]-Tabla15[[#This Row],[Previsión]] -> 0 | AA46: =SUM(INDEX(Tabla15[[#This Row],[Facturació A/A]],1):Tabla15[[#This Row],[Facturació A/A]]) / SUM(INDEX(Tabla15[[#This Row],[Diferencia]],1):Tabla15[[#This Row],[Diferencia]]) -> #DIV/0! | AB46: lluvias
... C54: 21 | D54: 46043 | E54: 47.7 | F54: =Tabla15[[#This Row],[Retiros]]-Tabla15[[#This Row],[Contado]] -> 183.3 | G54: 225 | H54: 0 | I54: 31.05 | J54: 0 | K54: 0 | L54: 0 | M54: 231 | N54: =Tabla15[[#This Row],[Contado]] -> 47.7 | P54: =((Tabla15[[#This Row],[Contado]]+Tabla15[[#This Row],[Visa]]+Tabla15[[#This Row],[Eventos]]+Tabla15[[#This Row],[Passo]]+Tabla15[[#This Row],[Reciclajes]])/1.1)+Tabla15[[#This Row],[Tickets]] -> 459.43636 | Q54: 0.21 | R54: =IFERROR(F54/P54,0) -> 0.39896711 | T54: 764.26 | U54: =Tabla15[[#This Row],[Total Caja]]-Tabla15[[#This Row],[Facturació A/A]] -> -304.82364 | V54: =U54+V53 -> -1296.0555 | W54: =Tabla15[[#This Row],[Diferencia]]/Tabla15[[#This Row],[Facturació A/A]] -> -0.39884808 | X54: =Tabla15[[#This Row],[Facturació A/A]]*H$17+Tabla15[[#This Row],[Facturació A/A]] -> 787.1878 | Y54: =Tabla15[[#This Row],[Total Caja]]-Tabla15[[#This Row],[Previsión]] -> -327.75144 | AA54: =SUM(INDEX(Tabla15[[#This Row],[Facturació A/A]],1):Tabla15[[#This Row],[Facturació A/A]]) / SUM(INDEX(Tabla15[[#This Row],[Diferencia]],1):Tabla15[[#This Row],[Diferencia]]) -> -2.5072203 | AB54: lluvias
C55: 22 | D55: 46044 | E55: 51.65 | F55: =Tabla15[[#This Row],[Retiros]]-Tabla15[[#This Row],[Contado]] -> 168.35 | G55: 678.4 | H55: 0 | I55: 0 | J55: 0 | K55: 0 | L55: 0 | M55: 220 | N55: =Tabla15[[#This Row],[Contado]] -> 51.65 | P55: =((Tabla15[[#This Row],[Contado]]+Tabla15[[#This Row],[Visa]]+Tabla15[[#This Row],[Eventos]]+Tabla15[[#This Row],[Passo]]+Tabla15[[#This Row],[Reciclajes]])/1.1)+Tabla15[[#This Row],[Tickets]] -> 832.03182 | Q55: 0.08 | R55: =IFERROR(F55/P55,0) -> 0.20233601 | T55: 467.08 | U55: =Tabla15[[#This Row],[Total Caja]]-Tabla15[[#This Row],[Facturació A/A]] -> 364.95182 | V55: =U55+V54 -> -931.10364 | W55: =Tabla15[[#This Row],[Diferencia]]/Tabla15[[#This Row],[Facturació A/A]] -> 0.78134756 | X55: =Tabla15[[#This Row],[Facturació A/A]]*H$17+Tabla15[[#This Row],[Facturació A/A]] -> 481.0924 | Y55: =Tabla15[[#This Row],[Total Caja]]-Tabla15[[#This Row],[Previsión]] -> 350.93942 | AA55: =SUM(INDEX(Tabla15[[#This Row],[Facturació A/A]],1):Tabla15[[#This Row],[Facturació A/A]]) / SUM(INDEX(Tabla15[[#This Row],[Diferencia]],1):Tabla15[[#This Row],[Diferencia]]) -> 1.2798402
C56: 23 | D56: 46045 | E56: 18.9 | F56: =Tabla15[[#This Row],[Retiros]]-Tabla15[[#This Row],[Contado]] -> 216.1 | G56: 1056.85 | H56: 0 | I56: 0 | J56: 0 | K56: 0 | L56: 0 | M56: 235 | N56: =Tabla15[[#This Row],[Contado]] -> 18.9 | P56: =((Tabla15[[#This Row],[Contado]]+Tabla15[[#This Row],[Visa]]+Tabla15[[#This Row],[Eventos]]+Tabla15[[#This Row],[Passo]]+Tabla15[[#This Row],[Reciclajes]])/1.1)+Tabla15[[#This Row],[Tickets]] -> 1194.0545 | Q56: 0.02 | R56: =IFERROR(F56/P56,0) -> 0.18098001 | T56: 1203.5 | U56: =Tabla15[[#This Row],[Total Caja]]-Tabla15[[#This Row],[Facturació A/A]] -> -9.4454545 | V56: =U56+V55 -> -940.54909 | W56: =Tabla15[[#This Row],[Diferencia]]/Tabla15[[#This Row],[Facturació A/A]] -> -0.0078483212 | X56: =Tabla15[[#This Row],[Facturació A/A]]*H$17+Tabla15[[#This Row],[Facturació A/A]] -> 1239.605 | Y56: =Tabla15[[#This Row],[Total Caja]]-Tabla15[[#This Row],[Previsión]] -> -45.550455 | AA56: =SUM(INDEX(Tabla15[[#This Row],[Facturació A/A]],1):Tabla15[[#This Row],[Facturació A/A]]) / SUM(INDEX(Tabla15[[#This Row],[Diferencia]],1):Tabla15[[#This Row],[Diferencia]]) -> -127.41578
C57: 24 | D57: 46046 | E57: 393.15 | F57: =Tabla15[[#This Row],[Retiros]]-Tabla15[[#This Row],[Contado]] -> 86.85 | G57: 1203.05 | H57: 0 | I57: 17.5 | J57: 0 | K57: 0 | L57: 0 | M57: 480 | N57: =Tabla15[[#This Row],[Contado]] -> 393.15 | P57: =((Tabla15[[#This Row],[Contado]]+Tabla15[[#This Row],[Visa]]+Tabla15[[#This Row],[Eventos]]+Tabla15[[#This Row],[Passo]]+Tabla15[[#This Row],[Reciclajes]])/1.1)+Tabla15[[#This Row],[Tickets]] -> 1553.85 | Q57: 0.33 | R57: =IFERROR(F57/P57,0) -> 0.055893426 | T57: 2204.06 | U57: =Tabla15[[#This Row],[Total Caja]]-Tabla15[[#This Row],[Facturació A/A]] -> -650.21 | V57: =U57+V56 -> -1590.7591 | W57: =Tabla15[[#This Row],[Diferencia]]/Tabla15[[#This Row],[Facturació A/A]] -> -0.29500558 | X57: =Tabla15[[#This Row],[Facturació A/A]]*H$17+Tabla15[[#This Row],[Facturació A/A]] -> 2270.1818 | Y57: =Tabla15[[#This Row],[Total Caja]]-Tabla15[[#This Row],[Previsión]] -> -716.3318 | AA57: =SUM(INDEX(Tabla15[[#This Row],[Facturació A/A]],1):Tabla15[[#This Row],[Facturació A/A]]) / SUM(INDEX(Tabla15[[#This Row],[Diferencia]],1):Tabla15[[#This Row],[Diferencia]]) -> -3.3897664
C58: 25 | D58: 46047 | E58: 759.1 | F58: =Tabla15[[#This Row],[Retiros]]-Tabla15[[#This Row],[Contado]] -> 140.9 | G58: 1072.5 | H58: 0 | I58: 23.8 | J58: 0 | K58: 0 | L58: 0 | M58: 900 | N58: =Tabla15[[#This Row],[Contado]] -> 759.1 | P58: =((Tabla15[[#This Row],[Contado]]+Tabla15[[#This Row],[Visa]]+Tabla15[[#This Row],[Eventos]]+Tabla15[[#This Row],[Passo]]+Tabla15[[#This Row],[Reciclajes]])/1.1)+Tabla15[[#This Row],[Tickets]] -> 1827.6273 | Q58: 0.71 | R58: =IFERROR(F58/P58,0) -> 0.077094494 | T58: 1303.8 | U58: =Tabla15[[#This Row],[Total Caja]]-Tabla15[[#This Row],[Facturació A/A]] -> 523.82727 | V58: =U58+V57 -> -1066.9318 | W58: =Tabla15[[#This Row],[Diferencia]]/Tabla15[[#This Row],[Facturació A/A]] -> 0.40176965 | X58: =Tabla15[[#This Row],[Facturació A/A]]*H$17+Tabla15[[#This Row],[Facturació A/A]] -> 1342.914 | Y58: =Tabla15[[#This Row],[Total Caja]]-Tabla15[[#This Row],[Previsión]] -> 484.71327 | AA58: =SUM(INDEX(Tabla15[[#This Row],[Facturació A/A]],1):Tabla15[[#This Row],[Facturació A/A]]) / SUM(INDEX(Tabla15[[#This Row],[Diferencia]],1):Tabla15[[#This Row],[Diferencia]]) -> 2.4889884
...

Sheet Caja 1
A1: TAPERIA DE CALDES · CAJA 1 — REGISTRO DIARIO DE VENTAS | L1: RESUMEN MENSUAL
A2: 📘 CÓMO USAR: Introduce cada día los importes por turno. Los totales se calculan automáticamente. Azul = dato a introducir · Verde = cálculo automático | L2: Mes | O2: Comensales | P2: Facturación € | Q2: Ticket Medio € | R2: Coste Personal € | S2: Margen € | T2: % Coste
A3: Fecha | B3: Día | C3: Turno | D3: Nº Comensales | E3: Subtotal € | F3: Ticket Medio € | G3: Coste Personal € | H3: Margen € | I3: % Coste | J3: Notas / Evento | L3: Enero | O3: {=SUMPRODUCT(--(MONTH($A$4:$A$919+0)=ROW()-2),$D$4:$D$919)} -> 759 | P3: {=SUMPRODUCT(--(MONTH($A$4:$A$919+0)=ROW()-2),$E$4:$E$919)} -> 3490.48 | Q3: =IFERROR(P3/O3,0) -> 4.5987879 | R3: {=SUMPRODUCT(--(MONTH($A$4:$A$919+0)=ROW()-2),$G$4:$G$919)} -> 0 | S3: =P3-R3 -> 3490.48 | T3: =IFERROR(R3/P3,0) -> 0
A4: 46024 | B4: =IF(A4="","",CHOOSE(WEEKDAY(A4,2),"Lun","Mar","Mié","Jue","Vie","Sáb","Dom")) -> Vie | C4: Mañana | D4: {=IF(A4="","",SUMPRODUCT(('Detalle Turnos'!$I$3:$I$5028=$A4)*('Detalle Turnos'!$N$3:$N$5028=C4)*'Detalle Turnos'!$L$3:$L$5028))} -> 27 | E4: {=IF(A4="","",SUMPRODUCT(('Detalle Turnos'!$I$3:$I$5028=$A4)*('Detalle Turnos'!$N$3:$N$5028=C4)*'Detalle Turnos'!$K$3:$K$5028))} -> 89.25 | F4: =IFERROR(E4/D4,0) -> 3.3055556 | G4: {=IF(E4="","",IFERROR(SUMPRODUCT(('Facturación 2026'!$A$4:$A$920=$A4)*'Facturación 2026'!$J$4:$J$920)*E4/(SUMPRODUCT(('Caja 1'!$A$4:$A$919=$A4)*'Caja 1'!$E$4:$E$919)+SUMPRODUCT(('Caja 2'!$A$4:$A$920=$A4)*'Caja 2'!$E$4:$E$920)),0))} -> 0 | H4: =IF(E4="","",E4-G4) -> 89.25 | I4: =IF(E4="","",IFERROR(G4/E4,0)) -> 0 | J4: =IF(A4="","",IFERROR(INDEX('Facturación 2026'!$L$4:$L$500,MATCH($A4,'Facturación 2026'!$A$4:$A$500,0)),"")) | L4: Febrero | O4: {=SUMPRODUCT(--(MONTH($A$4:$A$919+0)=ROW()-2),$D$4:$D$919)} -> 711 | P4: {=SUMPRODUCT(--(MONTH($A$4:$A$919+0)=ROW()-2),$E$4:$E$919)} -> 4552.59 | Q4: =IFERROR(P4/O4,0) -> 6.4030802 | R4: {=SUMPRODUCT(--(MONTH($A$4:$A$919+0)=ROW()-2),$G$4:$G$919)} -> 0 | S4: =P4-R4 -> 4552.59 | T4: =IFERROR(R4/P4,0) -> 0
A5: 46024 | B5: =IF(A5="","",CHOOSE(WEEKDAY(A5,2),"Lun","Mar","Mié","Jue","Vie","Sáb","Dom")) -> Vie | C5: Mediodia | D5: {=IF(A5="","",SUMPRODUCT(('Detalle Turnos'!$I$3:$I$5028=$A5)*('Detalle Turnos'!$N$3:$N$5028=C5)*'Detalle Turnos'!$L$3:$L$5028))} -> 9 | E5: {=IF(A5="","",SUMPRODUCT(('Detalle Turnos'!$I$3:$I$5028=$A5)*('Detalle Turnos'!$N$3:$N$5028=C5)*'Detalle Turnos'!$K$3:$K$5028))} -> 90.65 | F5: =IFERROR(E5/D5,0) -> 10.072222 | G5: {=IF(E5="","",IFERROR(SUMPRODUCT(('Facturación 2026'!$A$4:$A$920=$A5)*'Facturación 2026'!$J$4:$J$920)*E5/(SUMPRODUCT(('Caja 1'!$A$4:$A$919=$A5)*'Caja 1'!$E$4:$E$919)+SUMPRODUCT(('Caja 2'!$A$4:$A$920=$A5)*'Caja 2'!$E$4:$E$920)),0))} -> 0 | H5: =IF(E5="","",E5-G5) -> 90.65 | I5: =IF(E5="","",IFERROR(G5/E5,0)) -> 0 | J5: =IF(A5="","",IFERROR(INDEX('Facturación 2026'!$L$4:$L$500,MATCH($A5,'Facturación 2026'!$A$4:$A$500,0)),"")) | L5: Marzo | O5: {=SUMPRODUCT(--(MONTH($A$4:$A$919+0)=ROW()-2),$D$4:$D$919)} -> 593 | P5: {=SUMPRODUCT(--(MONTH($A$4:$A$919+0)=ROW()-2),$E$4:$E$919)} -> 3863.29 | Q5: =IFERROR(P5/O5,0) -> 6.5148229 | R5: {=SUMPRODUCT(--(MONTH($A$4:$A$919+0)=ROW()-2),$G$4:$G$919)} -> 0 | S5: =P5-R5 -> 3863.29 | T5: =IFERROR(R5/P5,0) -> 0
A6: 46025 | B6: =IF(A6="","",CHOOSE(WEEKDAY(A6,2),"Lun","Mar","Mié","Jue","Vie","Sáb","Dom")) -> Sáb | C6: Mañana | D6: {=IF(A6="","",SUMPRODUCT(('Detalle Turnos'!$I$3:$I$5028=$A6)*('Detalle Turnos'!$N$3:$N$5028=C6)*'Detalle Turnos'!$L$3:$L$5028))} -> 24 | E6: {=IF(A6="","",SUMPRODUCT(('Detalle Turnos'!$I$3:$I$5028=$A6)*('Detalle Turnos'!$N$3:$N$5028=C6)*'Detalle Turnos'!$K$3:$K$5028))} -> 106.05 | F6: =IFERROR(E6/D6,0) -> 4.41875 | G6: {=IF(E6="","",IFERROR(SUMPRODUCT(('Facturación 2026'!$A$4:$A$920=$A6)*'Facturación 2026'!$J$4:$J$920)*E6/(SUMPRODUCT(('Caja 1'!$A$4:$A$919=$A6)*'Caja 1'!$E$4:$E$919)+SUMPRODUCT(('Caja 2'!$A$4:$A$920=$A6)*'Caja 2'!$E$4:$E$920)),0))} -> 0 | H6: =IF(E6="","",E6-G6) -> 106.05 | I6: =IF(E6="","",IFERROR(G6/E6,0)) -> 0 | J6: =IF(A6="","",IFERROR(INDEX('Facturación 2026'!$L$4:$L$500,MATCH($A6,'Facturación 2026'!$A$4:$A$500,0)),"")) | L6: Abril | O6: {=SUMPRODUCT(--(MONTH($A$4:$A$919+0)=ROW()-2),$D$4:$D$919)} -> 595 | P6: {=SUMPRODUCT(--(MONTH($A$4:$A$919+0)=ROW()-2),$E$4:$E$919)} -> 5126.65 | Q6: =IFERROR(P6/O6,0) -> 8.6162185 | R6: {=SUMPRODUCT(--(MONTH($A$4:$A$919+0)=ROW()-2),$G$4:$G$919)} -> 0 | S6: =P6-R6 -> 5126.65 | T6: =IFERROR(R6/P6,0) -> 0
A7: 46025 | B7: =IF(A7="","",CHOOSE(WEEKDAY(A7,2),"Lun","Mar","Mié","Jue","Vie","Sáb","Dom")) -> Sáb | C7: Mediodia | D7: {=IF(A7="","",SUMPRODUCT(('Detalle Turnos'!$I$3:$I$5028=$A7)*('Detalle Turnos'!$N$3:$N$5028=C7)*'Detalle Turnos'!$L$3:$L$5028))} -> 4 | E7: {=IF(A7="","",SUMPRODUCT(('Detalle Turnos'!$I$3:$I$5028=$A7)*('Detalle Turnos'!$N$3:$N$5028=C7)*'Detalle Turnos'!$K$3:$K$5028))} -> 5.15 | F7: =IFERROR(E7/D7,0) -> 1.2875 | G7: {=IF(E7="","",IFERROR(SUMPRODUCT(('Facturación 2026'!$A$4:$A$920=$A7)*'Facturación 2026'!$J$4:$J$920)*E7/(SUMPRODUCT(('Caja 1'!$A$4:$A$919=$A7)*'Caja 1'!$E$4:$E$919)+SUMPRODUCT(('Caja 2'!$A$4:$A$920=$A7)*'Caja 2'!$E$4:$E$920)),0))} -> 0 | H7: =IF(E7="","",E7-G7) -> 5.15 | I7: =IF(E7="","",IFERROR(G7/E7,0)) -> 0 | J7: =IF(A7="","",IFERROR(INDEX('Facturación 2026'!$L$4:$L$500,MATCH($A7,'Facturación 2026'!$A$4:$A$500,0)),"")) | L7: TOTAL ANUAL | O7: {=SUMPRODUCT(--(MONTH($A$4:$A$919+0)=ROW()-2),$D$4:$D$919)} -> 23 | P7: {=SUMPRODUCT(--(MONTH($A$4:$A$919+0)=ROW()-2),$E$4:$E$919)} -> 75.3 | Q7: =IFERROR(P7/O7,0) -> 3.273913 | R7: {=SUMPRODUCT(--(MONTH($A$4:$A$919+0)=ROW()-2),$G$4:$G$919)} -> 0 | S7: =P7-R7 -> 75.3 | T7: =IFERROR(R7/P7,0) -> 0
A8: 46026 | B8: =IF(A8="","",CHOOSE(WEEKDAY(A8,2),"Lun","Mar","Mié","Jue","Vie","Sáb","Dom")) -> Dom | C8: Mañana | D8: {=IF(A8="","",SUMPRODUCT(('Detalle Turnos'!$I$3:$I$5028=$A8)*('Detalle Turnos'!$N$3:$N$5028=C8)*'Detalle Turnos'!$L$3:$L$5028))} -> 17 | E8: {=IF(A8="","",SUMPRODUCT(('Detalle Turnos'!$I$3:$I$5028=$A8)*('Detalle Turnos'!$N$3:$N$5028=C8)*'Detalle Turnos'!$K$3:$K$5028))} -> 58.4 | F8: =IFERROR(E8/D8,0) -> 3.4352941 | G8: {=IF(E8="","",IFERROR(SUMPRODUCT(('Facturación 2026'!$A$4:$A$920=$A8)*'Facturación 2026'!$J$4:$J$920)*E8/(SUMPRODUCT(('Caja 1'!$A$4:$A$919=$A8)*'Caja 1'!$E$4:$E$919)+SUMPRODUCT(('Caja 2'!$A$4:$A$920=$A8)*'Caja 2'!$E$4:$E$920)),0))} -> 0 | H8: =IF(E8="","",E8-G8) -> 58.4 | I8: =IF(E8="","",IFERROR(G8/E8,0)) -> 0 | J8: =IF(A8="","",IFERROR(INDEX('Facturación 2026'!$L$4:$L$500,MATCH($A8,'Facturación 2026'!$A$4:$A$500,0)),"")) | L8: Total | O8: =SUM(O3:O7) -> 2681 | P8: =SUM(P3:P7) -> 17108.31 | Q8: =IFERROR(P8/O8,0) -> 6.3813167 | R8: =SUM(R3:R7) -> 0 | S8: =P8-R8 -> 17108.31 | T8: =IFERROR(R8/P8,0) -> 0
A9: 46026 | B9: =IF(A9="","",CHOOSE(WEEKDAY(A9,2),"Lun","Mar","Mié","Jue","Vie","Sáb","Dom")) -> Dom | C9: Mediodia | D9: {=IF(A9="","",SUMPRODUCT(('Detalle Turnos'!$I$3:$I$5028=$A9)*('Detalle Turnos'!$N$3:$N$5028=C9)*'Detalle Turnos'!$L$3:$L$5028))} -> 7 | E9: {=IF(A9="","",SUMPRODUCT(('Detalle Turnos'!$I$3:$I$5028=$A9)*('Detalle Turnos'!$N$3:$N$5028=C9)*'Detalle Turnos'!$K$3:$K$5028))} -> 17.7 | F9: =IFERROR(E9/D9,0) -> 2.5285714 | G9: {=IF(E9="","",IFERROR(SUMPRODUCT(('Facturación 2026'!$A$4:$A$920=$A9)*'Facturación 2026'!$J$4:$J$920)*E9/(SUMPRODUCT(('Caja 1'!$A$4:$A$919=$A9)*'Caja 1'!$E$4:$E$919)+SUMPRODUCT(('Caja 2'!$A$4:$A$920=$A9)*'Caja 2'!$E$4:$E$920)),0))} -> 0 | H9: =IF(E9="","",E9-G9) -> 17.7 | I9: =IF(E9="","",IFERROR(G9/E9,0)) -> 0 | J9: =IF(A9="","",IFERROR(INDEX('Facturación 2026'!$L$4:$L$500,MATCH($A9,'Facturación 2026'!$A$4:$A$500,0)),"")) | L9: ANÁLISIS POR TURNO
A10: 46029 | B10: =IF(A10="","",CHOOSE(WEEKDAY(A10,2),"Lun","Mar","Mié","Jue","Vie","Sáb","Dom")) -> Mié | C10: Mañana | D10: {=IF(A10="","",SUMPRODUCT(('Detalle Turnos'!$I$3:$I$5028=$A10)*('Detalle Turnos'!$N$3:$N$5028=C10)*'Detalle Turnos'!$L$3:$L$5028))} -> 22 | E10: {=IF(A10="","",SUMPRODUCT(('Detalle Turnos'!$I$3:$I$5028=$A10)*('Detalle Turnos'!$N$3:$N$5028=C10)*'Detalle Turnos'!$K$3:$K$5028))} -> 58.35 | F10: =IFERROR(E10/D10,0) -> 2.6522727 | G10: {=IF(E10="","",IFERROR(SUMPRODUCT(('Facturación 2026'!$A$4:$A$920=$A10)*'Facturación 2026'!$J$4:$J$920)*E10/(SUMPRODUCT(('Caja 1'!$A$4:$A$919=$A10)*'Caja 1'!$E$4:$E$919)+SUMPRODUCT(('Caja 2'!$A$4:$A$920=$A10)*'Caja 2'!$E$4:$E$920)),0))} -> 0 | H10: =IF(E10="","",E10-G10) -> 58.35 | I10: =IF(E10="","",IFERROR(G10/E10,0)) -> 0 | J10: =IF(A10="","",IFERROR(INDEX('Facturación 2026'!$L$4:$L$500,MATCH($A10,'Facturación 2026'!$A$4:$A$500,0)),"")) | L10: Turno | O10: Comensales | P10: Facturación € | Q10: % del Total | R10: Ticket Medio € | S10: Margen € | T10: % Coste
A11: 46029 | B11: =IF(A11="","",CHOOSE(WEEKDAY(A11,2),"Lun","Mar","Mié","Jue","Vie","Sáb","Dom")) -> Mié | C11: Mediodia | D11: {=IF(A11="","",SUMPRODUCT(('Detalle Turnos'!$I$3:$I$5028=$A11)*('Detalle Turnos'!$N$3:$N$5028=C11)*'Detalle Turnos'!$L$3:$L$5028))} -> 13 | E11: {=IF(A11="","",SUMPRODUCT(('Detalle Turnos'!$I$3:$I$5028=$A11)*('Detalle Turnos'!$N$3:$N$5028=C11)*'Detalle Turnos'!$K$3:$K$5028))} -> 127.75 | F11: =IFERROR(E11/D11,0) -> 9.8269231 | G11: {=IF(E11="","",IFERROR(SUMPRODUCT(('Facturación 2026'!$A$4:$A$920=$A11)*'Facturación 2026'!$J$4:$J$920)*E11/(SUMPRODUCT(('Caja 1'!$A$4:$A$919=$A11)*'Caja 1'!$E$4:$E$919)+SUMPRODUCT(('Caja 2'!$A$4:$A$920=$A11)*'Caja 2'!$E$4:$E$920)),0))} -> 0 | H11: =IF(E11="","",E11-G11) -> 127.75 | I11: =IF(E11="","",IFERROR(G11/E11,0)) -> 0 | J11: =IF(A11="","",IFERROR(INDEX('Facturación 2026'!$L$4:$L$500,MATCH($A11,'Facturación 2026'!$A$4:$A$500,0)),"")) | L11: Mañana | O11: {=SUMPRODUCT(--($C$4:$C$919="Mañana"),$D$4:$D$919)} -> 1480 | P11: {=SUMPRODUCT(--($C$4:$C$919="Mañana"),$E$4:$E$919)} -> 5052.09 | Q11: =IFERROR(P11/SUM($E$4:$E$919),0) -> 0.29530035 | R11: =IFERROR(P11/O11,0) -> 3.4135743 | S11: {=SUMPRODUCT(--($C$4:$C$919="Mañana"),$H$4:$H$919)} -> 5052.09 | T11: =IFERROR(1-S11/P11,0) -> 0
